ValueError: Value of 'x' is not the name of a column in 'data_frame'. Expected one of [] but received: date
Traceback:
File "/home/runner/workspace/.pythonlibs/lib/python3.11/site-packages/streamlit/runtime/scriptrunner/exec_code.py", line 121, in exec_func_with_error_handling
    result = func()
             ^^^^^^
File "/home/runner/workspace/.pythonlibs/lib/python3.11/site-packages/streamlit/runtime/scriptrunner/script_runner.py", line 647, in code_to_exec
    _mpa_v1(self._main_script_path)
File "/home/runner/workspace/.pythonlibs/lib/python3.11/site-packages/streamlit/runtime/scriptrunner/script_runner.py", line 166, in _mpa_v1
    page.run()
File "/home/runner/workspace/.pythonlibs/lib/python3.11/site-packages/streamlit/navigation/page.py", line 297, in run
    exec(code, module.__dict__)
File "/home/runner/workspace/pages/1_monitor_products.py", line 513, in <module>
    app()
File "/home/runner/workspace/pages/1_monitor_products.py", line 453, in app
    parity_fig = create_price_parity_chart(price_history, product_name)
                 ^^^^^^^^^^^^^^^^^^^^^^^^^^^^^^^^^^^^^^^^^^^^^^^^^^^^^^
File "/home/runner/workspace/utils/visualizations.py", line 952, in create_price_parity_chart
    fig = px.scatter(
          ^^^^^^^^^^^
File "/home/runner/workspace/.pythonlibs/lib/python3.11/site-packages/plotly/express/_chart_types.py", line 69, in scatter
    return make_figure(args=locals(), constructor=go.Scatter)
           ^^^^^^^^^^^^^^^^^^^^^^^^^^^^^^^^^^^^^^^^^^^^^^^^^^
File "/home/runner/workspace/.pythonlibs/lib/python3.11/site-packages/plotly/express/_core.py", line 2479, in make_figure
    args = build_dataframe(args, constructor)
           ^^^^^^^^^^^^^^^^^^^^^^^^^^^^^^^^^^
File "/home/runner/workspace/.pythonlibs/lib/python3.11/site-packages/plotly/express/_core.py", line 1727, in build_dataframe
    df_output, wide_id_vars = process_args_into_dataframe(
                              ^^^^^^^^^^^^^^^^^^^^^^^^^^^^
File "/home/runner/workspace/.pythonlibs/lib/python3.11/site-packages/plotly/express/_core.py", line 1328, in process_args_into_dataframe
    raise ValueError(err_msg)